Workbook

Sheet README
A1: Workbook | B1: REDU presentation-ready analysis workbook
A2: Source
A3: Formula policy | B3: Uses scalar Excel-compatible formulas: COUNTIFS, SUMIFS, AVERAGEIFS, INDEX, MATCH, TTEST, TDIST, TINV, CORREL, RANK, VAR, STDEV.
A4: Avoided | B4: FILTER, LET, UNIQUE, XLOOKUP, AGGREGATE array extraction, and implicit-intersection @ formulas were avoided to reduce Excel repair/compatibility issues.
A5: Raw tabs | B5: Canonical raw .csv sheets are kept at the end of the workbook for validation.
A6: Missing | B6: Open-ended feedback and SME sheets remain placeholders unless actual responses are collected.
A7: Guide | B7: See GUIDE for sheet purposes, interpretation thresholds, and missing-data cautions.

Sheet GUIDE
A1: REDU Statistician Guide and Interpretation Notes
A2: Use the PDF for methodology/interpretation review; use Excel for raw data, formulas, and audit trails. This guide summarizes the thesis context, workbook flow, terms, interpretation rules, and formula-audit rules.
A5: Thesis Overview
A6: Topic | B6: Description
A7: Project | B7: REDU: Doomscrolling Detection and Digital Mindfulness Mobile Application for Short-Form Video Platforms Using VADER and Fuzzy Logic.
A8: System purpose | B8: A privacy-preserving Android app that estimates doomscrolling-related risk from observable mobile-use signals. It is not a clinical diagnostic tool.
A9: Core pipeline | B9: The app logs short-form video sessions, extracts available text, applies VADER-compatible sentiment analysis with Filipino/Taglish support, uses an on-device VLM fallback for no-text items, and estimates session risk through fuzzy logic.
A10: Evaluation focus | B10: The workbook supports software acceptability, short-term behavioral comparison, baseline convergent association, prompt/data-quality summaries, and later SME validation when completed.
A12: Study Design and Workbook Flow
A13: Component | B13: What it means for analysis
A14: Week 1 baseline | B14: Logging period used for baseline usage metrics, fixed-prior DSI, and first Doomscrolling Scale administration.
A15: Week 2 comparison | B15: Intervention/control comparison period. Week 2 minus Week 1 change scores feed RQ2.
A16: Post-use survey | B16: Participants answer ISO/IEC 25010, SUS, TAM, and open-ended items. Survey wording is mapped in QUESTIONS.
A17: SME review | B17: SME sheets are placeholders unless completed expert responses are added; do not treat current blank SME sheets as RQ5 evidence.
A18: PDF companion | B18: PDF contains the assumption-selected reporting layer; Excel contains raw data, formulas, and audit trail.
A20: Research Questions and Sheet Map
A21: RQ | B21: Question focus | C21: Workbook evidence
A22: RQ1 | B22: System architecture and estimation framework | C22: Thesis chapters; not an inferential workbook test.
A23: RQ2 | B23: Week 1 to Week 2 usage/self-report differences | C23: CHANGE_SCORES, RQ2_CHANGE_TESTS, RQ2_GROUP_DATA, RQ2_PAIRED_INTERVENTION, RQ2_FINAL_TESTS_PDF_ALIGNED.
A24: RQ3 | B24: Baseline association between Week 1 DSI/app metrics and Week 1 Doomscrolling Scale | C24: RQ3_DATA and RQ3_CORRELATION.
A25: RQ4 | B25: User evaluation through ISO/IEC 25010, SUS, and TAM | C25: SURVEY_ANALYSIS, ISOIEC 25010, Usability(SUS), TAM(PUPEOU), SURVEY_SCORES.
A26: RQ5 | B26: SME evaluation | C26: sme_evaluation.csv and sme_open_ended_feedback.csv; placeholders until actual responses are entered.
A28: Important Terms
A29: Term | B29: Meaning
A30: Doomscrolling | B30: Compulsive or repeated consumption of negative/distressing online content.
A31: Session | B31: A logged short-form video platform use interval summarized by the app.
A32: Video dwell time | B32: Average time spent on viewed short-form video items, reported in seconds.
A33: NSD | B33: Negative Sentiment Density: percentage of resolved content units classified as negative.
A34: RiskScore | B34: Session-level fuzzy-logic output on a 0-100 scale.
A35: DSI | B35: Doomscroll Severity Index: week-level mean of reliable session RiskScores. It is an analytic index, not a diagnosis.
A36: OOV ratio | B36: Out-of-vocabulary token proportion. High OOV is a reliability concern, not a sentiment score.
A37: Sentiment-reliable session | B37: A session with enough reliable text or VLM-resolved content to include in NSD/DSI analysis.
A38: ISO/IEC 25010 | B38: Software-quality evaluation framework.
A39: SUS | B39: System Usability Scale; ten items scored to a 0-100 usability score.
A40: TAM | B40: Technology Acceptance Model; Perceived Usefulness and Perceived Ease of Use.
A41: SME | B41: Subject matter expert.
A43: Interpretation and Formula Audit Rules
A44: Rule | B44: Instruction
A45: ISO/TAM favorable target | B45: Mean >= 3.50.
A46: SUS usability target | B46: SUS score >= 70.
...

Sheet QUESTIONS
A1: Questionnaire Codebook
A2: Full administered item wording mapped to workbook variables. Raw q1/q2 headers remain unchanged so formulas and imports stay stable.
A3: Purpose | B3: Allows a statistician, adviser, or panel reader to audit the exact questionnaire wording without cross-checking external materials.
A6: Important note | B6: SME evaluation and SME open-ended sheets are placeholders unless actual expert responses are entered.
A7: Instrument | B7: Section / Construct | C7: Workbook sheet | D7: Workbook column | E7: Item no. | F7: Question / Item wording | G7: Response scale | H7: Scoring / interpretation | I7: Respondent | J7: Source
A8: Participant Form | B8: Study eligibility note | C8: Not stored in standardized raw tabs | F8: This study is open only to participants who are 18 years old and above, use an Android smartphone (Android 8.0 or higher), and are active users of short-form video platforms such as TikTok, Facebook Reels, or Instagram Reels. | G8: Information only | H8: Eligibility statement shown before consent. | I8: Participant
A9: Participant Form | B9: Data privacy notice | C9: Not stored in standardized raw tabs | F9: DATA PRIVACY ACT We are committed to upholding the rights of individuals to data privacy. We follow the principles of transparency, legitimate purpose, and proportionality in processing personal data. We comply with Republic Act No. 10173 or the Data Privacy Act of 2012, including its Implementing Rules and Regulations issued by the National Privacy Commission. All collected data will be used solely for academic research purposes and will be kept confidential. | G9: Information only | H9: Privacy notice shown before consent. | I9: Participant
A10: Participant Form | B10: Participant Consent | C10: Not stored in standardized raw tabs | E10: Consent 1 | F10: I have read and understood the Data Privacy Act statement above. | G10: Checkbox acknowledgment | H10: Required consent acknowledgment before participation. | I10: Participant
A11: Participant Form | B11: Participant Consent | C11: Not stored in standardized raw tabs | E11: Consent 2 | F11: I voluntarily agree to participate in this study. | G11: Checkbox acknowledgment | H11: Required consent acknowledgment before participation. | I11: Participant
A12: Participant Form | B12: Participant Consent | C12: Not stored in standardized raw tabs | E12: Consent 3 | F12: I understand that my responses will be used for academic research purposes only. | G12: Checkbox acknowledgment | H12: Required consent acknowledgment before participation. | I12: Participant
A13: Participant Form | B13: Eligibility | C13: Not stored in standardized raw tabs | F13: Are you 18 years old or above? | G13: Yes; No | H13: Screening/profile item; not part of ISO/SUS/TAM computation. | I13: Participant
A14: Participant Form | B14: Basic Information | C14: Not stored in standardized raw tabs | F14: What best describes your current role? | G14: Undergraduate Student; College Graduate | H14: Screening/profile item; not part of ISO/SUS/TAM computation. | I14: Participant
A15: Participant Form | B15: Media Platforms | C15: Not stored in standardized raw tabs | F15: Which of the following short-form video platforms do you currently use? | G15: Facebook; TikTok; Instagram | H15: Screening/profile item; not part of ISO/SUS/TAM computation. | I15: Participant
A16: Participant Form | B16: Device Screening | C16: Not stored in standardized raw tabs | F16: What device do you primarily use for short-form video apps? | G16: Android smartphone; Other (not included in study) | H16: Screening/profile item; not part of ISO/SUS/TAM computation. | I16: Participant
A17: ISO/IEC 25010 | B17: Functional Suitability | C17: survey_iso25010.csv | D17: functional_q1 | E17: Q1 | F17: The application performs intended functions correctly. | G17: 1=Strongly Disagree; 2=Disagree; 3=Neutral; 4=Agree; 5=Strongly Agree | H17: Compute construct mean and SD; favorable benchmark is mean >= 3.50. | I17: Participant
A18: ISO/IEC 25010 | B18: Functional Suitability | C18: survey_iso25010.csv | D18: functional_q2 | E18: Q2 | F18: The monitoring system works properly. | G18: 1=Strongly Disagree; 2=Disagree; 3=Neutral; 4=Agree; 5=Strongly Agree | H18: Compute construct mean and SD; favorable benchmark is mean >= 3.50. | I18: Participant
A19: ISO/IEC 25010 | B19: Functional Suitability | C19: survey_iso25010.csv | D19: functional_q3 | E19: Q3 | F19: Notifications appear appropriately. | G19: 1=Strongly Disagree; 2=Disagree; 3=Neutral; 4=Agree; 5=Strongly Agree | H19: Compute construct mean and SD; favorable benchmark is mean >= 3.50. | I19: Participant
A20: ISO/IEC 25010 | B20: Functional Suitability | C20: survey_iso25010.csv | D20: functional_q4 | E20: Q4 | F20: Dashboard information is useful. | G20: 1=Strongly Disagree; 2=Disagree; 3=Neutral; 4=Agree; 5=Strongly Agree | H20: Compute construct mean and SD; favorable benchmark is mean >= 3.50. | I20: Participant
A21: ISO/IEC 25010 | B21: Functional Suitability | C21: survey_iso25010.csv | D21: functional_q5 | E21: Q5 | F21: Features support doomscrolling awareness. | G21: 1=Strongly Disagree; 2=Disagree; 3=Neutral; 4=Agree; 5=Strongly Agree | H21: Compute construct mean and SD; favorable benchmark is mean >= 3.50. | I21: Participant
A22: ISO/IEC 25010 | B22: Performance Efficiency | C22: survey_iso25010.csv | D22: performance_q1 | E22: Q1 | F22: App runs smoothly. | G22: 1=Strongly Disagree; 2=Disagree; 3=Neutral; 4=Agree; 5=Strongly Agree | H22: Compute construct mean and SD; favorable benchmark is mean >= 3.50. | I22: Participant
A23: ISO/IEC 25010 | B23: Performance Efficiency | C23: survey_iso25010.csv | D23: performance_q2 | E23: Q2 | F23: App does not slow device. | G23: 1=Strongly Disagree; 2=Disagree; 3=Neutral; 4=Agree; 5=Strongly Agree | H23: Compute construct mean and SD; favorable benchmark is mean >= 3.50. | I23: Participant
A24: ISO/IEC 25010 | B24: Performance Efficiency | C24: survey_iso25010.csv | D24: performance_q3 | E24: Q3 | F24: Battery use acceptable. | G24: 1=Strongly Disagree; 2=Disagree; 3=Neutral; 4=Agree; 5=Strongly Agree | H24: Compute construct mean and SD; favorable benchmark is mean >= 3.50. | I24: Participant
A25: ISO/IEC 25010 | B25: Performance Efficiency | C25: survey_iso25010.csv | D25: performance_q4 | E25: Q4 | F25: Fast response time. | G25: 1=Strongly Disagree; 2=Disagree; 3=Neutral; 4=Agree; 5=Strongly Agree | H25: Compute construct mean and SD; favorable benchmark is mean >= 3.50. | I25: Participant
A26: ISO/IEC 25010 | B26: Performance Efficiency | C26: survey_iso25010.csv | D26: performance_q5 | E26: Q5 | F26: Efficient resource usage. | G26: 1=Strongly Disagree; 2=Disagree; 3=Neutral; 4=Agree; 5=Strongly Agree | H26: Compute construct mean and SD; favorable benchmark is mean >= 3.50. | I26: Participant
A27: ISO/IEC 25010 | B27: Reliability | C27: survey_iso25010.csv | D27: reliability_q1 | E27: Q1 | F27: The application remained stable during use. | G27: 1=Strongly Disagree; 2=Disagree; 3=Neutral; 4=Agree; 5=Strongly Agree | H27: Compute construct mean and SD; favorable benchmark is mean >= 3.50. | I27: Participant
A28: ISO/IEC 25010 | B28: Reliability | C28: survey_iso25010.csv | D28: reliability_q2 | E28: Q2 | F28: The app rarely crashes or stops unexpectedly. | G28: 1=Strongly Disagree; 2=Disagree; 3=Neutral; 4=Agree; 5=Strongly Agree | H28: Compute construct mean and SD; favorable benchmark is mean >= 3.50. | I28: Participant
... A53: Technology Acceptance Model (TAM) | B53: Perceived Ease of Use (PEOU) | C53: tam_responses.csv | D53: peou_q6 | E53: Q6 | F53: Overall, the application is easy to use. | G53: 1=Strongly Disagree; 2=Disagree; 3=Neutral; 4=Agree; 5=Strongly Agree | H53: Compute construct mean and SD; favorable benchmark is mean >= 3.50. | I53: Participant
A54: Participant Open-Ended Feedback | B54: Strengths | C54: open_ended_feedback.csv | D54: liked_most | F54: What are the strengths of the proposed system? | G54: Free-text response | H54: Qualitative context only; theme coding can be entered in coded_theme after responses are collected. | I54: Participant
A55: Participant Open-Ended Feedback | B55: Areas for improvement | C55: open_ended_feedback.csv | D55: main_difficulty | F55: What areas of the system require improvement? | G55: Free-text response | H55: Qualitative context only; theme coding can be entered in coded_theme after responses are collected. | I55: Participant
A56: Participant Open-Ended Feedback | B56: Additional recommendations | C56: open_ended_feedback.csv | D56: suggested_improvement | F56: Additional recommendations: | G56: Free-text response | H56: Qualitative context only; theme coding can be entered in coded_theme after responses are collected. | I56: Participant
A57: Participant Open-Ended Feedback | B57: Privacy comment | C57: open_ended_feedback.csv | D57: privacy_comment | F57: Optional privacy-related participant comment, if collected or coded from open-ended feedback. | G57: Free-text response / coded note | H57: Qualitative context only; current participant form does not show this as a separate prompt. | I57: Participant
A58: Participant Open-Ended Feedback | B58: Coded theme | C58: open_ended_feedback.csv | D58: coded_theme | F58: Researcher-coded qualitative theme for participant feedback. | G58: Researcher-coded category | H58: Used only after actual open-ended responses are coded. | I58: Researcher
A59: Short-Form Doomscrolling Scale | B59: Past-week self-report | C59: doomscrolling_scale.csv | D59: ds_q1 | E59: Item 1 | F59: I feel an urge to seek bad news on social media, more and more often. | G59: 1=Strongly disagree; 2=Disagree; 3=Somewhat disagree; 4=Neither agree nor disagree; 5=Somewhat agree; 6=Agree; 7=Strongly agree | H59: Administered with the stem: In the past week, please indicate how strongly you agree with each statement. Score is the sum of the four items; higher score indicates stronger self-reported doomscrolling tendency. | I59: Participant
A60: Short-Form Doomscrolling Scale | B60: Past-week self-report | C60: doomscrolling_scale.csv | D60: ds_q2 | E60: Item 2 | F60: I lose track of time when I read bad news on social media. | G60: 1=Strongly disagree; 2=Disagree; 3=Somewhat disagree; 4=Neither agree nor disagree; 5=Somewhat agree; 6=Agree; 7=Strongly agree | H60: Administered with the stem: In the past week, please indicate how strongly you agree with each statement. Score is the sum of the four items; higher score indicates stronger self-reported doomscrolling tendency. | I60: Participant
A61: Short-Form Doomscrolling Scale | B61: Past-week self-report | C61: doomscrolling_scale.csv | D61: ds_q10 | E61: Item 10 | F61: I find myself continuously browsing negative news. | G61: 1=Strongly disagree; 2=Disagree; 3=Somewhat disagree; 4=Neither agree nor disagree; 5=Somewhat agree; 6=Agree; 7=Strongly agree | H61: Administered with the stem: In the past week, please indicate how strongly you agree with each statement. Score is the sum of the four items; higher score indicates stronger self-reported doomscrolling tendency. | I61: Participant
A62: Short-Form Doomscrolling Scale | B62: Past-week self-report | C62: doomscrolling_scale.csv | D62: ds_q12 | E62: Item 12 | F62: I feel like I am addicted to negative news. | G62: 1=Strongly disagree; 2=Disagree; 3=Somewhat disagree; 4=Neither agree nor disagree; 5=Somewhat agree; 6=Agree; 7=Strongly agree | H62: Administered with the stem: In the past week, please indicate how strongly you agree with each statement. Score is the sum of the four items; higher score indicates stronger self-reported doomscrolling tendency. | I62: Participant
A63: Short-Form Doomscrolling Scale | B63: Recall window | C63: doomscrolling_scale.csv | D63: recall_window | F63: Past 7 days. | G63: Fixed recall window | H63: Used for Week 1 and Week 2 administrations; change score is Week 2 minus Week 1. | I63: Participant
A64: SME Evaluation | B64: Structured expert rubric | C64: sme_evaluation.csv | D64: technical_soundness | F64: Technical soundness of the hybrid risk-estimation framework, including VADER integration and fuzzy inference behavior. | G64: 1=Strongly Disagree / Very Poor; 2=Disagree / Poor; 3=Neutral / Fair; 4=Agree / Good; 5=Strongly Agree / Excellent | H64: Compute mean and SD descriptively; favorable expert benchmark is mean >= 4.00. Current SME rows are placeholders unless completed responses are added. | I64: SME / expert
A65: SME Evaluation | B65: Structured expert rubric | C65: sme_evaluation.csv | D65: input_range_plausibility | F65: Plausibility of the selected input ranges for Video Dwell Time, Negative Sentiment Density, and Session Duration. | G65: 1=Strongly Disagree / Very Poor; 2=Disagree / Poor; 3=Neutral / Fair; 4=Agree / Good; 5=Strongly Agree / Excellent | H65: Compute mean and SD descriptively; favorable expert benchmark is mean >= 4.00. Current SME rows are placeholders unless completed responses are added. | I65: SME / expert
A66: SME Evaluation | B66: Structured expert rubric | C66: sme_evaluation.csv | D66: rule_base_coherence | F66: Internal coherence of the 27-rule base, including sensible direction across duration and negative exposure and reasonable exception rules. | G66: 1=Strongly Disagree / Very Poor; 2=Disagree / Poor; 3=Neutral / Fair; 4=Agree / Good; 5=Strongly Agree / Excellent | H66: Compute mean and SD descriptively; favorable expert benchmark is mean >= 4.00. Current SME rows are placeholders unless completed responses are added. | I66: SME / expert
...

Sheet STATISTICIAN_SIGNOFF
A1: Statistician Validation and Sign-Off
A2: This page is reserved for the statistician or adviser to confirm that the workbook data structure, formulas, and computations were reviewed. Leave blank until signed.
A5: Review Scope
A6: Item | B6: Review Area | C6: Confirmation / Notes | D6: Initials
A7: 1 | B7: Raw data tabs reviewed
A8: 2 | B8: Survey scoring and thresholds reviewed
A9: 3 | B9: Week 1 / Week 2 computations reviewed
A10: 4 | B10: RQ2 statistical tests reviewed
A11: 5 | B11: RQ3 correlation computations reviewed
A12: 6 | B12: Formula compatibility checked
A13: 7 | B13: Missing qualitative / SME data noted
A16: Sign-Off
A18: Statistician / Validator Name
A20: Professional Title / Affiliation
A22: License / Registration No. (if applicable)
A24: Date Reviewed
A27: Signature
D31: Place signature inside the box above.
A34: Validation Statement: I have reviewed the relevant workbook sheets, visible formulas, questionnaire mapping, and analysis outputs for consistency with the stated computation plan. Any exceptions or qualifications may be written in the notes area above.

Sheet PDF_ALIGNMENT_NOTES
A1: PDF and Excel Alignment Notes
A2: Use the PDF for methodology/interpretation review; use Excel for raw data, formulas, and audit trails. This sheet records known alignment points and differences so the statistician does not see a silent mismatch.
A5: Where PDF and Excel Agree
A6: Area | B6: Alignment note
A7: Sample size | B7: Both documents use N = 50, with intervention/control target split 25/25.
A8: Raw sessions | B8: Excel contains 10,134 logged sessions in sessions.csv; PDF reports 10,134 logged sessions.
A9: Reliability status | B9: PDF reports 8,817 reliable sessions and 1,317 sentiment-unreliable sessions; Excel raw sheets contain the same reliability-event structure and session reliability flags.
A10: Survey constructs | B10: Both use ISO/IEC 25010, SUS, TAM, and the 4-item Doomscrolling Scale.
A11: Thresholds | B11: Both use ISO/TAM >= 3.50, SUS >= 70, SME >= 4.00, Cronbach alpha >= 0.70, and p < .05.
A12: Open-ended and SME data | B12: Both indicate participant open-ended feedback and SME evaluation are not yet collected/completed.
A13: DSI/RQ3 framing | B13: Both treat DSI/RQ3 as baseline convergent plausibility evidence, not diagnostic validation.
A15: Known Differences and How to Read Them
A16: Issue | B16: Excel status | C16: PDF status | D16: Review instruction
A17: RQ2 final test selection | B17: Existing RQ2_CHANGE_TESTS computes Welch-style reference formulas for all change-score outcomes. | C17: PDF reports final assumption-selected tests: duration uses Welch; dwell, NSD, and Doomscrolling use Mann-Whitney U. | D17: Use RQ2_FINAL_TESTS_PDF_ALIGNED for final reporting values; use RQ2_CHANGE_TESTS for formula audit/reference.
A18: Within-intervention tests | B18: Existing RQ2_PAIRED_INTERVENTION computes paired t-test formulas for all outcomes. | C18: PDF reports paired t-test for duration/dwell and Wilcoxon fallback for NSD/Doomscrolling. | D18: Use the PDF-aligned sheet for final method labels and values.
A19: Effect sizes and CIs | B19: Excel Welch reference sheet contains formula-based Cohen d and CI fields for t-test route. | C19: PDF includes final effect sizes/CIs matched to the selected test route. | D19: Treat PDF-aligned final values as statistician-review values.
A20: Prompt-excluded active-use metrics | B20: Excel raw sessions include prompt_excluded_duration_ms, but no final prompt-excluded comparison sheet is present. | C20: PDF explicitly says this comparison is not separately computed in this export. | D20: Do not report prompt-excluded comparisons unless a new analysis sheet is added later.
A22: Companion Files
A23: File | B23: Role
A24: Statistician_Validation_Package.pdf | B24: Readable methodology, validation questions, assumption-selected final RQ2 results, and sign-off package.
A25: REDU ANALYSIS RESULT - STATISTICIAN READY - PDF ALIGNED.xlsx | B25: Raw data tabs, Excel formulas, questionnaire/codebook, PDF alignment notes, and formula audit trail.

Sheet EXECUTIVE_SUMMARY
A1: REDU Quantitative Analysis Summary | H1: What this sheet is for
A2: Section | B2: Metric | C2: Value / Formula | D2: Status | E2: Source | F2: Notes | H2: Quick view of participant counts, survey targets, RQ2/RQ3 statistics, and missing qualitative/SME data.
A3: Study | B3: Participants | C3: =COUNTA(study_periods.csv!$A$2:$A$51) -> 50 | E3: study_periods.csv | F3: Expected N = 50.
A4: Study | B4: Intervention group | C4: =COUNTIF(study_periods.csv!$B$2:$B$51,"INTERVENTION") -> 25 | E4: study_periods.csv | H4: How to read it: Use this as a navigation summary. Validate detailed calculations in the named source sheets.
A5: Study | B5: Control group | C5: =COUNTIF(study_periods.csv!$B$2:$B$51,"CONTROL") -> 25 | E5: study_periods.csv
A6: RQ4 | B6: ISO/SUS/TAM targets | C6: =COUNTIF(SURVEY_ANALYSIS!$H$2:$H$7,"Met")&" of "&COUNTA(SURVEY_ANALYSIS!$A$2:$A$7)&" met" -> 6 of 6 met | E6: SURVEY_ANALYSIS
A7: RQ2 | B7: Duration change p | C7: =RQ2_CHANGE_TESTS!K3 -> 0.00023630003 | D7: =RQ2_CHANGE_TESTS!N3 -> 0.0069484649 | E7: RQ2_CHANGE_TESTS | F7: Welch test on change scores.
A8: RQ2 | B8: Dwell change p | C8: =RQ2_CHANGE_TESTS!K4 -> 3.0285527e-05 | D8: =RQ2_CHANGE_TESTS!N4 -> 0.0069484649 | E8: RQ2_CHANGE_TESTS
A9: RQ2 | B9: NSD change p | C9: =RQ2_CHANGE_TESTS!K5 -> 1.4422395e-06 | D9: =RQ2_CHANGE_TESTS!N5 -> 0.0069484649 | E9: RQ2_CHANGE_TESTS
A10: RQ2 | B10: Doomscrolling score change p | C10: =RQ2_CHANGE_TESTS!K7 -> 4.4272306e-06 | D10: =RQ2_CHANGE_TESTS!N7 -> 0.0069484649 | E10: RQ2_CHANGE_TESTS
A11: RQ3 | B11: Week 1 DSI Pearson r | C11: =RQ3_CORRELATION!E5 -> 0.82474855 | D11: =RQ3_CORRELATION!G5 -> 5.7492061e-13 | E11: RQ3_CORRELATION | F11: Eligible participants only.
A12: Missing | B12: Open-ended feedback | C12: Blank placeholder | D12: Not ready | E12: open_ended_feedback.csv | F12: Qualitative themes still require actual participant responses (Phase 5). Still outstanding.
A13: Missing | B13: SME evaluation | C13: Partial - mobile rubric transcribed | D13: Partial | E13: sme_evaluation.csv | F13: SME-MOB-01 rubric in sme_evaluation (Approved, all 5s); SME-PSY-01 rubric PENDING - signed narrative validation on file (expert-review/), excerpts in sme_open_ended_feedback.

Sheet SURVEY_ANALYSIS
A1: construct | B1: n | C1: items | D1: mean | E1: sd | F1: cronbach_alpha | G1: threshold | H1: target_status | I1: metric | K1: What this sheet is for
A2: Functional Suitability | B2: =COUNTA(SURVEY_SCORES!$A$2:$A$51) -> 50 | C2: 5 | D2: =AVERAGE(SURVEY_SCORES!$B$2:$B$51) -> 3.928 | E2: =STDEV(SURVEY_SCORES!$B$2:$B$51) -> 0.50103566 | F2: =(5/(5-1))*(1-(SUM(VAR(survey_iso25010.csv!$B$2:$B$51),VAR(survey_iso25010.csv!$C$2:$C$51),VAR(survey_iso25010.csv!$D$2:$D$51),VAR(survey_iso25010.csv!$E$2:$E$51),VAR(survey_iso25010.csv!$F$2:$F$51))/VAR(survey_iso25010.csv!$G$2:$G$51))) -> 0.85246488 | G2: 3.5 | H2: =IF(D2>=G2,"Met","Not met") -> Met | I2: Likert mean | K2: Computes ISO, SUS, TAM means, standard deviations, Cronbach alpha, thresholds, and Met/Not met status.
A3: Performance Efficiency | B3: =COUNTA(SURVEY_SCORES!$A$2:$A$51) -> 50 | C3: 5 | D3: =AVERAGE(SURVEY_SCORES!$C$2:$C$51) -> 4.088 | E3: =STDEV(SURVEY_SCORES!$C$2:$C$51) -> 0.54982001 | F3: =(5/(5-1))*(1-(SUM(VAR(survey_iso25010.csv!$H$2:$H$51),VAR(survey_iso25010.csv!$I$2:$I$51),VAR(survey_iso25010.csv!$J$2:$J$51),VAR(survey_iso25010.csv!$K$2:$K$51),VAR(survey_iso25010.csv!$L$2:$L$51))/VAR(survey_iso25010.csv!$M$2:$M$51))) -> 0.85939188 | G3: 3.5 | H3: =IF(D3>=G3,"Met","Not met") -> Met | I3: Likert mean
A4: Reliability | B4: =COUNTA(SURVEY_SCORES!$A$2:$A$51) -> 50 | C4: 5 | D4: =AVERAGE(SURVEY_SCORES!$D$2:$D$51) -> 4.048 | E4: =STDEV(SURVEY_SCORES!$D$2:$D$51) -> 0.49743834 | F4: =(5/(5-1))*(1-(SUM(VAR(survey_iso25010.csv!$N$2:$N$51),VAR(survey_iso25010.csv!$O$2:$O$51),VAR(survey_iso25010.csv!$P$2:$P$51),VAR(survey_iso25010.csv!$Q$2:$Q$51),VAR(survey_iso25010.csv!$R$2:$R$51))/VAR(survey_iso25010.csv!$S$2:$S$51))) -> 0.71720771 | G4: 3.5 | H4: =IF(D4>=G4,"Met","Not met") -> Met | I4: Likert mean | K4: How to read it: Interpret ISO/TAM means >= 3.50 as favorable, SUS >= 70 as favorable, and alpha >= 0.70 as acceptable internal consistency.
A5: SUS Usability | B5: =COUNTA(SURVEY_SCORES!$A$2:$A$51) -> 50 | C5: 10 | D5: =AVERAGE(SURVEY_SCORES!$E$2:$E$51) -> 80.95 | E5: =STDEV(SURVEY_SCORES!$E$2:$E$51) -> 14.828011 | F5: =(10/(10-1))*(1-(SUM(VAR(SURVEY_SCORES!$H$2:$H$51),VAR(SURVEY_SCORES!$I$2:$I$51),VAR(SURVEY_SCORES!$J$2:$J$51),VAR(SURVEY_SCORES!$K$2:$K$51),VAR(SURVEY_SCORES!$L$2:$L$51),VAR(SURVEY_SCORES!$M$2:$M$51),VAR(SURVEY_SCORES!$N$2:$N$51),VAR(SURVEY_SCORES!$O$2:$O$51),VAR(SURVEY_SCORES!$P$2:$P$51),VAR(SURVEY_SCORES!$Q$2:$Q$51))/VAR(SURVEY_SCORES!$R$2:$R$51))) -> 0.95670883 | G5: 70 | H5: =IF(D5>=G5,"Met","Not met") -> Met | I5: SUS 0-100
A6: TAM Perceived Usefulness | B6: =COUNTA(SURVEY_SCORES!$A$2:$A$51) -> 50 | C6: 6 | D6: =AVERAGE(SURVEY_SCORES!$F$2:$F$51) -> 4.1166667 | E6: =STDEV(SURVEY_SCORES!$F$2:$F$51) -> 0.40159828 | F6: =(6/(6-1))*(1-(SUM(VAR(tam_responses.csv!$B$2:$B$51),VAR(tam_responses.csv!$C$2:$C$51),VAR(tam_responses.csv!$D$2:$D$51),VAR(tam_responses.csv!$E$2:$E$51),VAR(tam_responses.csv!$F$2:$F$51),VAR(tam_responses.csv!$G$2:$G$51))/VAR(tam_responses.csv!$H$2:$H$51))) -> 0.74977856 | G6: 3.5 | H6: =IF(D6>=G6,"Met","Not met") -> Met | I6: Likert mean
A7: TAM Perceived Ease of Use | B7: =COUNTA(SURVEY_SCORES!$A$2:$A$51) -> 50 | C7: 6 | D7: =AVERAGE(SURVEY_SCORES!$G$2:$G$51) -> 4.09 | E7: =STDEV(SURVEY_SCORES!$G$2:$G$51) -> 0.53474516 | F7: =(6/(6-1))*(1-(SUM(VAR(tam_responses.csv!$I$2:$I$51),VAR(tam_responses.csv!$J$2:$J$51),VAR(tam_responses.csv!$K$2:$K$51),VAR(tam_responses.csv!$L$2:$L$51),VAR(tam_responses.csv!$M$2:$M$51),VAR(tam_responses.csv!$N$2:$N$51))/VAR(tam_responses.csv!$O$2:$O$51))) -> 0.85538242 | G7: 3.5 | H7: =IF(D7>=G7,"Met","Not met") -> Met | I7: Likert mean

Sheet ISOIEC 25010
A1: ISO/IEC 25010 User Evaluation | AC1: What this sheet is for
AC2: Participant software-quality ratings for Functional Suitability, Performance Efficiency, and Reliability.
A3: Numerical Rating | B3: Mean Score Range | C3: Likert Interpretation | E3: I. Functional Suitability | M3: II. Performance Efficiency | U3: III. Reliability
A4: 5 | B4: 4.21 - 5.00 | C4: Strongly Agree | E4: Respondents | F4: Q1 | G4: Q2 | H4: Q3 | I4: Q4 | J4: Q5 | K4: TOTAL | M4: Respondents | N4: Q1 | O4: Q2 | P4: Q3 | Q4: Q4 | R4: Q5 | S4: TOTAL | U4: Respondents | V4: Q1 | W4: Q2 | X4: Q3 | Y4: Q4 | Z4: Q5 | AA4: TOTAL | AC4: How to read it: Use the Likert legend on the left. Construct means >= 3.50 meet the thesis favorable target.
A5: 4 | B5: 3.50 - 4.20 | C5: Agree | E5: =survey_iso25010.csv!A2 -> R1 | F5: =survey_iso25010.csv!B2 -> 4 | G5: =survey_iso25010.csv!C2 -> 4 | H5: =survey_iso25010.csv!D2 -> 4 | I5: =survey_iso25010.csv!E2 -> 4 | J5: =survey_iso25010.csv!F2 -> 4 | K5: =SUM(F5:J5) -> 20 | M5: =survey_iso25010.csv!A2 -> R1 | N5: =survey_iso25010.csv!H2 -> 4 | O5: =survey_iso25010.csv!I2 -> 3 | P5: =survey_iso25010.csv!J2 -> 4 | Q5: =survey_iso25010.csv!K2 -> 5 | R5: =survey_iso25010.csv!L2 -> 4 | S5: =SUM(N5:R5) -> 20 | U5: =survey_iso25010.csv!A2 -> R1 | V5: =survey_iso25010.csv!N2 -> 4 | W5: =survey_iso25010.csv!O2 -> 4 | X5: =survey_iso25010.csv!P2 -> 5 | Y5: =survey_iso25010.csv!Q2 -> 5 | Z5: =survey_iso25010.csv!R2 -> 3 | AA5: =SUM(V5:Z5) -> 21
A6: 3 | B6: 2.61 - 3.49 | C6: Neutral | E6: =survey_iso25010.csv!A3 -> R2 | F6: =survey_iso25010.csv!B3 -> 4 | G6: =survey_iso25010.csv!C3 -> 4 | H6: =survey_iso25010.csv!D3 -> 4 | I6: =survey_iso25010.csv!E3 -> 3 | J6: =survey_iso25010.csv!F3 -> 4 | K6: =SUM(F6:J6) -> 19 | M6: =survey_iso25010.csv!A3 -> R2 | N6: =survey_iso25010.csv!H3 -> 4 | O6: =survey_iso25010.csv!I3 -> 3 | P6: =survey_iso25010.csv!J3 -> 3 | Q6: =survey_iso25010.csv!K3 -> 3 | R6: =survey_iso25010.csv!L3 -> 4 | S6: =SUM(N6:R6) -> 17 | U6: =survey_iso25010.csv!A3 -> R2 | V6: =survey_iso25010.csv!N3 -> 4 | W6: =survey_iso25010.csv!O3 -> 3 | X6: =survey_iso25010.csv!P3 -> 4 | Y6: =survey_iso25010.csv!Q3 -> 3 | Z6: =survey_iso25010.csv!R3 -> 4 | AA6: =SUM(V6:Z6) -> 18
A7: 2 | B7: 1.81 - 2.60 | C7: Disagree | E7: =survey_iso25010.csv!A4 -> R3 | F7: =survey_iso25010.csv!B4 -> 4 | G7: =survey_iso25010.csv!C4 -> 4 | H7: =survey_iso25010.csv!D4 -> 4 | I7: =survey_iso25010.csv!E4 -> 4 | J7: =survey_iso25010.csv!F4 -> 4 | K7: =SUM(F7:J7) -> 20 | M7: =survey_iso25010.csv!A4 -> R3 | N7: =survey_iso25010.csv!H4 -> 4 | O7: =survey_iso25010.csv!I4 -> 4 | P7: =survey_iso25010.csv!J4 -> 4 | Q7: =survey_iso25010.csv!K4 -> 4 | R7: =survey_iso25010.csv!L4 -> 4 | S7: =SUM(N7:R7) -> 20 | U7: =survey_iso25010.csv!A4 -> R3 | V7: =survey_iso25010.csv!N4 -> 4 | W7: =survey_iso25010.csv!O4 -> 4 | X7: =survey_iso25010.csv!P4 -> 4 | Y7: =survey_iso25010.csv!Q4 -> 4 | Z7: =survey_iso25010.csv!R4 -> 4 | AA7: =SUM(V7:Z7) -> 20
A8: 1 | B8: 1.00 - 1.80 | C8: Strongly Disagree | E8: =survey_iso25010.csv!A5 -> R4 | F8: =survey_iso25010.csv!B5 -> 4 | G8: =survey_iso25010.csv!C5 -> 4 | H8: =survey_iso25010.csv!D5 -> 4 | I8: =survey_iso25010.csv!E5 -> 4 | J8: =survey_iso25010.csv!F5 -> 4 | K8: =SUM(F8:J8) -> 20 | M8: =survey_iso25010.csv!A5 -> R4 | N8: =survey_iso25010.csv!H5 -> 4 | O8: =survey_iso25010.csv!I5 -> 5 | P8: =survey_iso25010.csv!J5 -> 5 | Q8: =survey_iso25010.csv!K5 -> 5 | R8: =survey_iso25010.csv!L5 -> 5 | S8: =SUM(N8:R8) -> 24 | U8: =survey_iso25010.csv!A5 -> R4 | V8: =survey_iso25010.csv!N5 -> 5 | W8: =survey_iso25010.csv!O5 -> 5 | X8: =survey_iso25010.csv!P5 -> 3 | Y8: =survey_iso25010.csv!Q5 -> 5 | Z8: =survey_iso25010.csv!R5 -> 5 | AA8: =SUM(V8:Z8) -> 23
E9: =survey_iso25010.csv!A6 -> R5 | F9: =survey_iso25010.csv!B6 -> 4 | G9: =survey_iso25010.csv!C6 -> 4 | H9: =survey_iso25010.csv!D6 -> 4 | I9: =survey_iso25010.csv!E6 -> 4 | J9: =survey_iso25010.csv!F6 -> 4 | K9: =SUM(F9:J9) -> 20 | M9: =survey_iso25010.csv!A6 -> R5 | N9: =survey_iso25010.csv!H6 -> 5 | O9: =survey_iso25010.csv!I6 -> 5 | P9: =survey_iso25010.csv!J6 -> 5 | Q9: =survey_iso25010.csv!K6 -> 5 | R9: =survey_iso25010.csv!L6 -> 5 | S9: =SUM(N9:R9) -> 25 | U9: =survey_iso25010.csv!A6 -> R5 | V9: =survey_iso25010.csv!N6 -> 4 | W9: =survey_iso25010.csv!O6 -> 4 | X9: =survey_iso25010.csv!P6 -> 3 | Y9: =survey_iso25010.csv!Q6 -> 3 | Z9: =survey_iso25010.csv!R6 -> 3 | AA9: =SUM(V9:Z9) -> 17
E10: =survey_iso25010.csv!A7 -> R6 | F10: =survey_iso25010.csv!B7 -> 3 | G10: =survey_iso25010.csv!C7 -> 3 | H10: =survey_iso25010.csv!D7 -> 3 | I10: =survey_iso25010.csv!E7 -> 3 | J10: =survey_iso25010.csv!F7 -> 3 | K10: =SUM(F10:J10) -> 15 | M10: =survey_iso25010.csv!A7 -> R6 | N10: =survey_iso25010.csv!H7 -> 3 | O10: =survey_iso25010.csv!I7 -> 3 | P10: =survey_iso25010.csv!J7 -> 3 | Q10: =survey_iso25010.csv!K7 -> 3 | R10: =survey_iso25010.csv!L7 -> 3 | S10: =SUM(N10:R10) -> 15 | U10: =survey_iso25010.csv!A7 -> R6 | V10: =survey_iso25010.csv!N7 -> 3 | W10: =survey_iso25010.csv!O7 -> 3 | X10: =survey_iso25010.csv!P7 -> 3 | Y10: =survey_iso25010.csv!Q7 -> 3 | Z10: =survey_iso25010.csv!R7 -> 3 | AA10: =SUM(V10:Z10) -> 15
E11: =survey_iso25010.csv!A8 -> R7 | F11: =survey_iso25010.csv!B8 -> 4 | G11: =survey_iso25010.csv!C8 -> 4 | H11: =survey_iso25010.csv!D8 -> 4 | I11: =survey_iso25010.csv!E8 -> 4 | J11: =survey_iso25010.csv!F8 -> 4 | K11: =SUM(F11:J11) -> 20 | M11: =survey_iso25010.csv!A8 -> R7 | N11: =survey_iso25010.csv!H8 -> 4 | O11: =survey_iso25010.csv!I8 -> 4 | P11: =survey_iso25010.csv!J8 -> 4 | Q11: =survey_iso25010.csv!K8 -> 4 | R11: =survey_iso25010.csv!L8 -> 4 | S11: =SUM(N11:R11) -> 20 | U11: =survey_iso25010.csv!A8 -> R7 | V11: =survey_iso25010.csv!N8 -> 4 | W11: =survey_iso25010.csv!O8 -> 4 | X11: =survey_iso25010.csv!P8 -> 4 | Y11: =survey_iso25010.csv!Q8 -> 4 | Z11: =survey_iso25010.csv!R8 -> 4 | AA11: =SUM(V11:Z11) -> 20
E12: =survey_iso25010.csv!A9 -> R8 | F12: =survey_iso25010.csv!B9 -> 3 | G12: =survey_iso25010.csv!C9 -> 3 | H12: =survey_iso25010.csv!D9 -> 3 | I12: =survey_iso25010.csv!E9 -> 3 | J12: =survey_iso25010.csv!F9 -> 3 | K12: =SUM(F12:J12) -> 15 | M12: =survey_iso25010.csv!A9 -> R8 | N12: =survey_iso25010.csv!H9 -> 3 | O12: =survey_iso25010.csv!I9 -> 3 | P12: =survey_iso25010.csv!J9 -> 3 | Q12: =survey_iso25010.csv!K9 -> 4 | R12: =survey_iso25010.csv!L9 -> 4 | S12: =SUM(N12:R12) -> 17 | U12: =survey_iso25010.csv!A9 -> R8 | V12: =survey_iso25010.csv!N9 -> 4 | W12: =survey_iso25010.csv!O9 -> 4 | X12: =survey_iso25010.csv!P9 -> 4 | Y12: =survey_iso25010.csv!Q9 -> 4 | Z12: =survey_iso25010.csv!R9 -> 4 | AA12: =SUM(V12:Z12) -> 20
E13: =survey_iso25010.csv!A10 -> R9 | F13: =survey_iso25010.csv!B10 -> 4 | G13: =survey_iso25010.csv!C10 -> 4 | H13: =survey_iso25010.csv!D10 -> 4 | I13: =survey_iso25010.csv!E10 -> 4 | J13: =survey_iso25010.csv!F10 -> 4 | K13: =SUM(F13:J13) -> 20 | M13: =survey_iso25010.csv!A10 -> R9 | N13: =survey_iso25010.csv!H10 -> 4 | O13: =survey_iso25010.csv!I10 -> 4 | P13: =survey_iso25010.csv!J10 -> 4 | Q13: =survey_iso25010.csv!K10 -> 4 | R13: =survey_iso25010.csv!L10 -> 4 | S13: =SUM(N13:R13) -> 20 | U13: =survey_iso25010.csv!A10 -> R9 | V13: =survey_iso25010.csv!N10 -> 4 | W13: =survey_iso25010.csv!O10 -> 4 | X13: =survey_iso25010.csv!P10 -> 4 | Y13: =survey_iso25010.csv!Q10 -> 4 | Z13: =survey_iso25010.csv!R10 -> 4 | AA13: =SUM(V13:Z13) -> 20
E14: =survey_iso25010.csv!A11 -> R10 | F14: =survey_iso25010.csv!B11 -> 3 | G14: =survey_iso25010.csv!C11 -> 3 | H14: =survey_iso25010.csv!D11 -> 3 | I14: =survey_iso25010.csv!E11 -> 3 | J14: =survey_iso25010.csv!F11 -> 3 | K14: =SUM(F14:J14) -> 15 | M14: =survey_iso25010.csv!A11 -> R10 | N14: =survey_iso25010.csv!H11 -> 3 | O14: =survey_iso25010.csv!I11 -> 3 | P14: =survey_iso25010.csv!J11 -> 3 | Q14: =survey_iso25010.csv!K11 -> 3 | R14: =survey_iso25010.csv!L11 -> 3 | S14: =SUM(N14:R14) -> 15 | U14: =survey_iso25010.csv!A11 -> R10 | V14: =survey_iso25010.csv!N11 -> 3 | W14: =survey_iso25010.csv!O11 -> 3 | X14: =survey_iso25010.csv!P11 -> 3 | Y14: =survey_iso25010.csv!Q11 -> 3 | Z14: =survey_iso25010.csv!R11 -> 3 | AA14: =SUM(V14:Z14) -> 15
E15: =survey_iso25010.csv!A12 -> R11 | F15: =survey_iso25010.csv!B12 -> 5 | G15: =survey_iso25010.csv!C12 -> 5 | H15: =survey_iso25010.csv!D12 -> 5 | I15: =survey_iso25010.csv!E12 -> 5 | J15: =survey_iso25010.csv!F12 -> 5 | K15: =SUM(F15:J15) -> 25 | M15: =survey_iso25010.csv!A12 -> R11 | N15: =survey_iso25010.csv!H12 -> 5 | O15: =survey_iso25010.csv!I12 -> 4 | P15: =survey_iso25010.csv!J12 -> 4 | Q15: =survey_iso25010.csv!K12 -> 5 | R15: =survey_iso25010.csv!L12 -> 5 | S15: =SUM(N15:R15) -> 23 | U15: =survey_iso25010.csv!A12 -> R11 | V15: =survey_iso25010.csv!N12 -> 5 | W15: =survey_iso25010.csv!O12 -> 5 | X15: =survey_iso25010.csv!P12 -> 5 | Y15: =survey_iso25010.csv!Q12 -> 4 | Z15: =survey_iso25010.csv!R12 -> 5 | AA15: =SUM(V15:Z15) -> 24
E16: =survey_iso25010.csv!A13 -> R12 | F16: =survey_iso25010.csv!B13 -> 4 | G16: =survey_iso25010.csv!C13 -> 4 | H16: =survey_iso25010.csv!D13 -> 4 | I16: =survey_iso25010.csv!E13 -> 4 | J16: =survey_iso25010.csv!F13 -> 4 | K16: =SUM(F16:J16) -> 20 | M16: =survey_iso25010.csv!A13 -> R12 | N16: =survey_iso25010.csv!H13 -> 4 | O16: =survey_iso25010.csv!I13 -> 4 | P16: =survey_iso25010.csv!J13 -> 4 | Q16: =survey_iso25010.csv!K13 -> 4 | R16: =survey_iso25010.csv!L13 -> 4 | S16: =SUM(N16:R16) -> 20 | U16: =survey_iso25010.csv!A13 -> R12 | V16: =survey_iso25010.csv!N13 -> 4 | W16: =survey_iso25010.csv!O13 -> 4 | X16: =survey_iso25010.csv!P13 -> 4 | Y16: =survey_iso25010.csv!Q13 -> 4 | Z16: =survey_iso25010.csv!R13 -> 4 | AA16: =SUM(V16:Z16) -> 20
E17: =survey_iso25010.csv!A14 -> R13 | F17: =survey_iso25010.csv!B14 -> 5 | G17: =survey_iso25010.csv!C14 -> 4 | H17: =survey_iso25010.csv!D14 -> 5 | I17: =survey_iso25010.csv!E14 -> 3 | J17: =survey_iso25010.csv!F14 -> 4 | K17: =SUM(F17:J17) -> 21 | M17: =survey_iso25010.csv!A14 -> R13 | N17: =survey_iso25010.csv!H14 -> 5 | O17: =survey_iso25010.csv!I14 -> 4 | P17: =survey_iso25010.csv!J14 -> 4 | Q17: =survey_iso25010.csv!K14 -> 3 | R17: =survey_iso25010.csv!L14 -> 4 | S17: =SUM(N17:R17) -> 20 | U17: =survey_iso25010.csv!A14 -> R13 | V17: =survey_iso25010.csv!N14 -> 5 | W17: =survey_iso25010.csv!O14 -> 3 | X17: =survey_iso25010.csv!P14 -> 4 | Y17: =survey_iso25010.csv!Q14 -> 5 | Z17: =survey_iso25010.csv!R14 -> 3 | AA17: =SUM(V17:Z17) -> 20
E18: =survey_iso25010.csv!A15 -> R14 | F18: =survey_iso25010.csv!B15 -> 3 | G18: =survey_iso25010.csv!C15 -> 4 | H18: =survey_iso25010.csv!D15 -> 4 | I18: =survey_iso25010.csv!E15 -> 3 | J18: =survey_iso25010.csv!F15 -> 4 | K18: =SUM(F18:J18) -> 18 | M18: =survey_iso25010.csv!A15 -> R14 | N18: =survey_iso25010.csv!H15 -> 4 | O18: =survey_iso25010.csv!I15 -> 5 | P18: =survey_iso25010.csv!J15 -> 5 | Q18: =survey_iso25010.csv!K15 -> 3 | R18: =survey_iso25010.csv!L15 -> 4 | S18: =SUM(N18:R18) -> 21 | U18: =survey_iso25010.csv!A15 -> R14 | V18: =survey_iso25010.csv!N15 -> 4 | W18: =survey_iso25010.csv!O15 -> 5 | X18: =survey_iso25010.csv!P15 -> 3 | Y18: =survey_iso25010.csv!Q15 -> 4 | Z18: =survey_iso25010.csv!R15 -> 4 | AA18: =SUM(V18:Z18) -> 20
E19: =survey_iso25010.csv!A16 -> R15 | F19: =survey_iso25010.csv!B16 -> 4 | G19: =survey_iso25010.csv!C16 -> 4 | H19: =survey_iso25010.csv!D16 -> 4 | I19: =survey_iso25010.csv!E16 -> 4 | J19: =survey_iso25010.csv!F16 -> 4 | K19: =SUM(F19:J19) -> 20 | M19: =survey_iso25010.csv!A16 -> R15 | N19: =survey_iso25010.csv!H16 -> 4 | O19: =survey_iso25010.csv!I16 -> 4 | P19: =survey_iso25010.csv!J16 -> 4 | Q19: =survey_iso25010.csv!K16 -> 4 | R19: =survey_iso25010.csv!L16 -> 4 | S19: =SUM(N19:R19) -> 20 | U19: =survey_iso25010.csv!A16 -> R15 | V19: =survey_iso25010.csv!N16 -> 3 | W19: =survey_iso25010.csv!O16 -> 3 | X19: =survey_iso25010.csv!P16 -> 5 | Y19: =survey_iso25010.csv!Q16 -> 5 | Z19: =survey_iso25010.csv!R16 -> 5 | AA19: =SUM(V19:Z19) -> 21
E20: =survey_iso25010.csv!A17 -> R16 | F20: =survey_iso25010.csv!B17 -> 4 | G20: =survey_iso25010.csv!C17 -> 4 | H20: =survey_iso25010.csv!D17 -> 4 | I20: =survey_iso25010.csv!E17 -> 3 | J20: =survey_iso25010.csv!F17 -> 3 | K20: =SUM(F20:J20) -> 18 | M20: =survey_iso25010.csv!A17 -> R16 | N20: =survey_iso25010.csv!H17 -> 4 | O20: =survey_iso25010.csv!I17 -> 4 | P20: =survey_iso25010.csv!J17 -> 5 | Q20: =survey_iso25010.csv!K17 -> 5 | R20: =survey_iso25010.csv!L17 -> 5 | S20: =SUM(N20:R20) -> 23 | U20: =survey_iso25010.csv!A17 -> R16 | V20: =survey_iso25010.csv!N17 -> 3 | W20: =survey_iso25010.csv!O17 -> 5 | X20: =survey_iso25010.csv!P17 -> 4 | Y20: =survey_iso25010.csv!Q17 -> 4 | Z20: =survey_iso25010.csv!R17 -> 5 | AA20: =SUM(V20:Z20) -> 21
... E54: =survey_iso25010.csv!A51 -> R50 | F54: =survey_iso25010.csv!B51 -> 4 | G54: =survey_iso25010.csv!C51 -> 4 | H54: =survey_iso25010.csv!D51 -> 4 | I54: =survey_iso25010.csv!E51 -> 4 | J54: =survey_iso25010.csv!F51 -> 3 | K54: =SUM(F54:J54) -> 19 | M54: =survey_iso25010.csv!A51 -> R50 | N54: =survey_iso25010.csv!H51 -> 4 | O54: =survey_iso25010.csv!I51 -> 4 | P54: =survey_iso25010.csv!J51 -> 4 | Q54: =survey_iso25010.csv!K51 -> 3 | R54: =survey_iso25010.csv!L51 -> 4 | S54: =SUM(N54:R54) -> 19 | U54: =survey_iso25010.csv!A51 -> R50 | V54: =survey_iso25010.csv!N51 -> 4 | W54: =survey_iso25010.csv!O51 -> 3 | X54: =survey_iso25010.csv!P51 -> 3 | Y54: =survey_iso25010.csv!Q51 -> 4 | Z54: =survey_iso25010.csv!R51 -> 4 | AA54: =SUM(V54:Z54) -> 18
E56: MEAN | K56: =SURVEY_ANALYSIS!D2 -> 3.928 | M56: MEAN | S56: =SURVEY_ANALYSIS!D3 -> 4.088 | U56: MEAN | AA56: =SURVEY_ANALYSIS!D4 -> 4.048
E57: STD | K57: =SURVEY_ANALYSIS!E2 -> 0.50103566 | M57: STD | S57: =SURVEY_ANALYSIS!E3 -> 0.54982001 | U57: STD | AA57: =SURVEY_ANALYSIS!E4 -> 0.49743834
E58: ALPHA | K58: =SURVEY_ANALYSIS!F2 -> 0.85246488 | M58: ALPHA | S58: =SURVEY_ANALYSIS!F3 -> 0.85939188 | U58: ALPHA | AA58: =SURVEY_ANALYSIS!F4 -> 0.71720771

Sheet Usability(SUS)
A1: System Usability Scale (SUS) | AA1: What this sheet is for
A2: SUS scored table (even-numbered items reverse-scored) | O2: Original raw SUS responses | AA2: SUS scoring table; even-numbered items are reverse-scored, final score is 0-100.
A3: Respondents | B3: Q1 | C3: Q2 | D3: Q3 | E3: Q4 | F3: Q5 | G3: Q6 | H3: Q7 | I3: Q8 | J3: Q9 | K3: Q10 | L3: SUS SCORE | M3: TOTAL | O3: Respondents | P3: Q1 | Q3: Q2 | R3: Q3 | S3: Q4 | T3: Q5 | U3: Q6 | V3: Q7 | W3: Q8 | X3: Q9 | Y3: Q10
A4: =sus_responses.csv!A2 -> R1 | B4: =sus_responses.csv!B2 -> 5 | C4: =6-sus_responses.csv!C2 -> 4 | D4: =sus_responses.csv!D2 -> 4 | E4: =6-sus_responses.csv!E2 -> 5 | F4: =sus_responses.csv!F2 -> 5 | G4: =6-sus_responses.csv!G2 -> 5 | H4: =sus_responses.csv!H2 -> 5 | I4: =6-sus_responses.csv!I2 -> 5 | J4: =sus_responses.csv!J2 -> 5 | K4: =6-sus_responses.csv!K2 -> 5 | L4: =(SUM(B4:K4)-10)*2.5 -> 95 | M4: =SUM(B4:K4) -> 48 | O4: =sus_responses.csv!A2 -> R1 | P4: =sus_responses.csv!B2 -> 5 | Q4: =sus_responses.csv!C2 -> 2 | R4: =sus_responses.csv!D2 -> 4 | S4: =sus_responses.csv!E2 -> 1 | T4: =sus_responses.csv!F2 -> 5 | U4: =sus_responses.csv!G2 -> 1 | V4: =sus_responses.csv!H2 -> 5 | ... Y4: =sus_responses.csv!K2 -> 1 | AA4: How to read it: SUS >= 70 meets the thesis usability target. Higher scores indicate better perceived usability.
A5: =sus_responses.csv!A3 -> R2 | B5: =sus_responses.csv!B3 -> 4 | C5: =6-sus_responses.csv!C3 -> 5 | D5: =sus_responses.csv!D3 -> 5 | E5: =6-sus_responses.csv!E3 -> 5 | F5: =sus_responses.csv!F3 -> 4 | G5: =6-sus_responses.csv!G3 -> 4 | H5: =sus_responses.csv!H3 -> 5 | I5: =6-sus_responses.csv!I3 -> 5 | J5: =sus_responses.csv!J3 -> 5 | K5: =6-sus_responses.csv!K3 -> 5 | L5: =(SUM(B5:K5)-10)*2.5 -> 92.5 | M5: =SUM(B5:K5) -> 47 | O5: =sus_responses.csv!A3 -> R2 | P5: =sus_responses.csv!B3 -> 4 | Q5: =sus_responses.csv!C3 -> 1 | R5: =sus_responses.csv!D3 -> 5 | S5: =sus_responses.csv!E3 -> 1 | T5: =sus_responses.csv!F3 -> 4 | U5: =sus_responses.csv!G3 -> 2 | V5: =sus_responses.csv!H3 -> 5 | ... Y5: =sus_responses.csv!K3 -> 1
A6: =sus_responses.csv!A4 -> R3 | B6: =sus_responses.csv!B4 -> 4 | C6: =6-sus_responses.csv!C4 -> 5 | D6: =sus_responses.csv!D4 -> 4 | E6: =6-sus_responses.csv!E4 -> 5 | F6: =sus_responses.csv!F4 -> 5 | G6: =6-sus_responses.csv!G4 -> 5 | H6: =sus_responses.csv!H4 -> 5 | I6: =6-sus_responses.csv!I4 -> 5 | J6: =sus_responses.csv!J4 -> 5 | K6: =6-sus_responses.csv!K4 -> 5 | L6: =(SUM(B6:K6)-10)*2.5 -> 95 | M6: =SUM(B6:K6) -> 48 | O6: =sus_responses.csv!A4 -> R3 | P6: =sus_responses.csv!B4 -> 4 | Q6: =sus_responses.csv!C4 -> 1 | R6: =sus_responses.csv!D4 -> 4 | S6: =sus_responses.csv!E4 -> 1 | T6: =sus_responses.csv!F4 -> 5 | U6: =sus_responses.csv!G4 -> 1 | V6: =sus_responses.csv!H4 -> 5 | ... Y6: =sus_responses.csv!K4 -> 1
A7: =sus_responses.csv!A5 -> R4 | B7: =sus_responses.csv!B5 -> 4 | C7: =6-sus_responses.csv!C5 -> 5 | D7: =sus_responses.csv!D5 -> 5 | E7: =6-sus_responses.csv!E5 -> 5 | F7: =sus_responses.csv!F5 -> 5 | G7: =6-sus_responses.csv!G5 -> 4 | H7: =sus_responses.csv!H5 -> 5 | I7: =6-sus_responses.csv!I5 -> 5 | J7: =sus_responses.csv!J5 -> 4 | K7: =6-sus_responses.csv!K5 -> 5 | L7: =(SUM(B7:K7)-10)*2.5 -> 92.5 | M7: =SUM(B7:K7) -> 47 | O7: =sus_responses.csv!A5 -> R4 | P7: =sus_responses.csv!B5 -> 4 | Q7: =sus_responses.csv!C5 -> 1 | R7: =sus_responses.csv!D5 -> 5 | S7: =sus_responses.csv!E5 -> 1 | T7: =sus_responses.csv!F5 -> 5 | U7: =sus_responses.csv!G5 -> 2 | V7: =sus_responses.csv!H5 -> 5 | ... Y7: =sus_responses.csv!K5 -> 1
A8: =sus_responses.csv!A6 -> R5 | B8: =sus_responses.csv!B6 -> 5 | C8: =6-sus_responses.csv!C6 -> 5 | D8: =sus_responses.csv!D6 -> 4 | E8: =6-sus_responses.csv!E6 -> 5 | F8: =sus_responses.csv!F6 -> 5 | G8: =6-sus_responses.csv!G6 -> 4 | H8: =sus_responses.csv!H6 -> 5 | I8: =6-sus_responses.csv!I6 -> 5 | J8: =sus_responses.csv!J6 -> 4 | K8: =6-sus_responses.csv!K6 -> 4 | L8: =(SUM(B8:K8)-10)*2.5 -> 90 | M8: =SUM(B8:K8) -> 46 | O8: =sus_responses.csv!A6 -> R5 | P8: =sus_responses.csv!B6 -> 5 | Q8: =sus_responses.csv!C6 -> 1 | R8: =sus_responses.csv!D6 -> 4 | S8: =sus_responses.csv!E6 -> 1 | T8: =sus_responses.csv!F6 -> 5 | U8: =sus_responses.csv!G6 -> 2 | V8: =sus_responses.csv!H6 -> 5 | ... Y8: =sus_responses.csv!K6 -> 2
A9: =sus_responses.csv!A7 -> R6 | B9: =sus_responses.csv!B7 -> 5 | C9: =6-sus_responses.csv!C7 -> 5 | D9: =sus_responses.csv!D7 -> 5 | E9: =6-sus_responses.csv!E7 -> 5 | F9: =sus_responses.csv!F7 -> 5 | G9: =6-sus_responses.csv!G7 -> 5 | H9: =sus_responses.csv!H7 -> 5 | I9: =6-sus_responses.csv!I7 -> 5 | J9: =sus_responses.csv!J7 -> 5 | K9: =6-sus_responses.csv!K7 -> 5 | L9: =(SUM(B9:K9)-10)*2.5 -> 100 | M9: =SUM(B9:K9) -> 50 | O9: =sus_responses.csv!A7 -> R6 | P9: =sus_responses.csv!B7 -> 5 | Q9: =sus_responses.csv!C7 -> 1 | R9: =sus_responses.csv!D7 -> 5 | S9: =sus_responses.csv!E7 -> 1 | T9: =sus_responses.csv!F7 -> 5 | U9: =sus_responses.csv!G7 -> 1 | V9: =sus_responses.csv!H7 -> 5 | ... Y9: =sus_responses.csv!K7 -> 1
A10: =sus_responses.csv!A8 -> R7 | B10: =sus_responses.csv!B8 -> 5 | C10: =6-sus_responses.csv!C8 -> 4 | D10: =sus_responses.csv!D8 -> 5 | E10: =6-sus_responses.csv!E8 -> 4 | F10: =sus_responses.csv!F8 -> 5 | G10: =6-sus_responses.csv!G8 -> 5 | H10: =sus_responses.csv!H8 -> 5 | I10: =6-sus_responses.csv!I8 -> 5 | J10: =sus_responses.csv!J8 -> 5 | K10: =6-sus_responses.csv!K8 -> 5 | L10: =(SUM(B10:K10)-10)*2.5 -> 95 | M10: =SUM(B10:K10) -> 48 | O10: =sus_responses.csv!A8 -> R7 | P10: =sus_responses.csv!B8 -> 5 | Q10: =sus_responses.csv!C8 -> 2 | R10: =sus_responses.csv!D8 -> 5 | S10: =sus_responses.csv!E8 -> 2 | T10: =sus_responses.csv!F8 -> 5 | U10: =sus_responses.csv!G8 -> 1 | V10: =sus_responses.csv!H8 -> 5 | ... Y10: =sus_responses.csv!K8 -> 1
A11: =sus_responses.csv!A9 -> R8 | B11: =sus_responses.csv!B9 -> 5 | C11: =6-sus_responses.csv!C9 -> 4 | D11: =sus_responses.csv!D9 -> 5 | E11: =6-sus_responses.csv!E9 -> 5 | F11: =sus_responses.csv!F9 -> 5 | G11: =6-sus_responses.csv!G9 -> 5 | H11: =sus_responses.csv!H9 -> 5 | I11: =6-sus_responses.csv!I9 -> 5 | J11: =sus_responses.csv!J9 -> 4 | K11: =6-sus_responses.csv!K9 -> 4 | L11: =(SUM(B11:K11)-10)*2.5 -> 92.5 | M11: =SUM(B11:K11) -> 47 | O11: =sus_responses.csv!A9 -> R8 | P11: =sus_responses.csv!B9 -> 5 | Q11: =sus_responses.csv!C9 -> 2 | R11: =sus_responses.csv!D9 -> 5 | S11: =sus_responses.csv!E9 -> 1 | T11: =sus_responses.csv!F9 -> 5 | U11: =sus_responses.csv!G9 -> 1 | V11: =sus_responses.csv!H9 -> 5 | ... Y11: =sus_responses.csv!K9 -> 2
A12: =sus_responses.csv!A10 -> R9 | B12: =sus_responses.csv!B10 -> 4 | C12: =6-sus_responses.csv!C10 -> 5 | D12: =sus_responses.csv!D10 -> 5 | E12: =6-sus_responses.csv!E10 -> 5 | F12: =sus_responses.csv!F10 -> 5 | G12: =6-sus_responses.csv!G10 -> 5 | H12: =sus_responses.csv!H10 -> 4 | I12: =6-sus_responses.csv!I10 -> 5 | J12: =sus_responses.csv!J10 -> 5 | K12: =6-sus_responses.csv!K10 -> 4 | L12: =(SUM(B12:K12)-10)*2.5 -> 92.5 | M12: =SUM(B12:K12) -> 47 | O12: =sus_responses.csv!A10 -> R9 | P12: =sus_responses.csv!B10 -> 4 | Q12: =sus_responses.csv!C10 -> 1 | R12: =sus_responses.csv!D10 -> 5 | S12: =sus_responses.csv!E10 -> 1 | T12: =sus_responses.csv!F10 -> 5 | U12: =sus_responses.csv!G10 -> 1 | V12: =sus_responses.csv!H10 -> 4 | ... Y12: =sus_responses.csv!K10 -> 2
A13: =sus_responses.csv!A11 -> R10 | B13: =sus_responses.csv!B11 -> 5 | C13: =6-sus_responses.csv!C11 -> 5 | D13: =sus_responses.csv!D11 -> 5 | E13: =6-sus_responses.csv!E11 -> 5 | F13: =sus_responses.csv!F11 -> 5 | G13: =6-sus_responses.csv!G11 -> 5 | H13: =sus_responses.csv!H11 -> 5 | I13: =6-sus_responses.csv!I11 -> 5 | J13: =sus_responses.csv!J11 -> 5 | K13: =6-sus_responses.csv!K11 -> 5 | L13: =(SUM(B13:K13)-10)*2.5 -> 100 | M13: =SUM(B13:K13) -> 50 | O13: =sus_responses.csv!A11 -> R10 | P13: =sus_responses.csv!B11 -> 5 | Q13: =sus_responses.csv!C11 -> 1 | R13: =sus_responses.csv!D11 -> 5 | S13: =sus_responses.csv!E11 -> 1 | T13: =sus_responses.csv!F11 -> 5 | U13: =sus_responses.csv!G11 -> 1 | V13: =sus_responses.csv!H11 -> 5 | ... Y13: =sus_responses.csv!K11 -> 1
A14: =sus_responses.csv!A12 -> R11 | B14: =sus_responses.csv!B12 -> 4 | C14: =6-sus_responses.csv!C12 -> 5 | D14: =sus_responses.csv!D12 -> 5 | E14: =6-sus_responses.csv!E12 -> 4 | F14: =sus_responses.csv!F12 -> 5 | G14: =6-sus_responses.csv!G12 -> 5 | H14: =sus_responses.csv!H12 -> 5 | I14: =6-sus_responses.csv!I12 -> 5 | J14: =sus_responses.csv!J12 -> 5 | K14: =6-sus_responses.csv!K12 -> 5 | L14: =(SUM(B14:K14)-10)*2.5 -> 95 | M14: =SUM(B14:K14) -> 48 | O14: =sus_responses.csv!A12 -> R11 | P14: =sus_responses.csv!B12 -> 4 | Q14: =sus_responses.csv!C12 -> 1 | R14: =sus_responses.csv!D12 -> 5 | S14: =sus_responses.csv!E12 -> 2 | T14: =sus_responses.csv!F12 -> 5 | U14: =sus_responses.csv!G12 -> 1 | V14: =sus_responses.csv!H12 -> 5 | ... Y14: =sus_responses.csv!K12 -> 1
A15: =sus_responses.csv!A13 -> R12 | B15: =sus_responses.csv!B13 -> 4 | C15: =6-sus_responses.csv!C13 -> 5 | D15: =sus_responses.csv!D13 -> 4 | E15: =6-sus_responses.csv!E13 -> 5 | F15: =sus_responses.csv!F13 -> 5 | G15: =6-sus_responses.csv!G13 -> 5 | H15: =sus_responses.csv!H13 -> 5 | I15: =6-sus_responses.csv!I13 -> 5 | J15: =sus_responses.csv!J13 -> 5 | K15: =6-sus_responses.csv!K13 -> 5 | L15: =(SUM(B15:K15)-10)*2.5 -> 95 | M15: =SUM(B15:K15) -> 48 | O15: =sus_responses.csv!A13 -> R12 | P15: =sus_responses.csv!B13 -> 4 | Q15: =sus_responses.csv!C13 -> 1 | R15: =sus_responses.csv!D13 -> 4 | S15: =sus_responses.csv!E13 -> 1 | T15: =sus_responses.csv!F13 -> 5 | U15: =sus_responses.csv!G13 -> 1 | V15: =sus_responses.csv!H13 -> 5 | ... Y15: =sus_responses.csv!K13 -> 1
A16: =sus_responses.csv!A14 -> R13 | B16: =sus_responses.csv!B14 -> 5 | C16: =6-sus_responses.csv!C14 -> 5 | D16: =sus_responses.csv!D14 -> 5 | E16: =6-sus_responses.csv!E14 -> 5 | F16: =sus_responses.csv!F14 -> 5 | G16: =6-sus_responses.csv!G14 -> 5 | H16: =sus_responses.csv!H14 -> 5 | I16: =6-sus_responses.csv!I14 -> 5 | J16: =sus_responses.csv!J14 -> 5 | K16: =6-sus_responses.csv!K14 -> 5 | L16: =(SUM(B16:K16)-10)*2.5 -> 100 | M16: =SUM(B16:K16) -> 50 | O16: =sus_responses.csv!A14 -> R13 | P16: =sus_responses.csv!B14 -> 5 | Q16: =sus_responses.csv!C14 -> 1 | R16: =sus_responses.csv!D14 -> 5 | S16: =sus_responses.csv!E14 -> 1 | T16: =sus_responses.csv!F14 -> 5 | U16: =sus_responses.csv!G14 -> 1 | V16: =sus_responses.csv!H14 -> 5 | ... Y16: =sus_responses.csv!K14 -> 1
... A53: =sus_responses.csv!A51 -> R50 | B53: =sus_responses.csv!B51 -> 4 | C53: =6-sus_responses.csv!C51 -> 3 | D53: =sus_responses.csv!D51 -> 3 | E53: =6-sus_responses.csv!E51 -> 3 | F53: =sus_responses.csv!F51 -> 3 | G53: =6-sus_responses.csv!G51 -> 4 | H53: =sus_responses.csv!H51 -> 3 | I53: =6-sus_responses.csv!I51 -> 3 | J53: =sus_responses.csv!J51 -> 3 | K53: =6-sus_responses.csv!K51 -> 3 | L53: =(SUM(B53:K53)-10)*2.5 -> 55 | M53: =SUM(B53:K53) -> 32 | O53: =sus_responses.csv!A51 -> R50 | P53: =sus_responses.csv!B51 -> 4 | Q53: =sus_responses.csv!C51 -> 3 | R53: =sus_responses.csv!D51 -> 3 | S53: =sus_responses.csv!E51 -> 3 | T53: =sus_responses.csv!F51 -> 3 | U53: =sus_responses.csv!G51 -> 2 | V53: =sus_responses.csv!H51 -> 3 | ... Y53: =sus_responses.csv!K51 -> 3
A55: MEAN | L55: =SURVEY_ANALYSIS!D5 -> 80.95
A56: STD | L56: =SURVEY_ANALYSIS!E5 -> 14.828011
A57: ALPHA | L57: =SURVEY_ANALYSIS!F5 -> 0.95670883

Sheet TAM(PUPEOU)
A1: Technology Acceptance Model (TAM) | S1: What this sheet is for
A2: I. Perceived Usefulness (PU) | J2: II. Perceived Ease of Use (PEOU) | S2: Participant acceptance ratings: Perceived Usefulness and Perceived Ease of Use.
A3: Respondents | B3: Q1 | C3: Q2 | D3: Q3 | E3: Q4 | F3: Q5 | G3: Q6 | H3: TOTAL | J3: Respondents | K3: Q1 | L3: Q2 | M3: Q3 | N3: Q4 | O3: Q5 | P3: Q6 | Q3: TOTAL
A4: =tam_responses.csv!A2 -> R1 | B4: =tam_responses.csv!B2 -> 5 | C4: =tam_responses.csv!C2 -> 5 | D4: =tam_responses.csv!D2 -> 4 | E4: =tam_responses.csv!E2 -> 4 | F4: =tam_responses.csv!F2 -> 3 | G4: =tam_responses.csv!G2 -> 4 | H4: =SUM(B4:G4) -> 25 | J4: =tam_responses.csv!A2 -> R1 | K4: =tam_responses.csv!I2 -> 4 | L4: =tam_responses.csv!J2 -> 5 | M4: =tam_responses.csv!K2 -> 5 | N4: =tam_responses.csv!L2 -> 5 | O4: =tam_responses.csv!M2 -> 5 | P4: =tam_responses.csv!N2 -> 5 | Q4: =SUM(K4:P4) -> 29 | S4: How to read it: PU and PEOU means >= 3.50 meet the thesis favorable target.
A5: =tam_responses.csv!A3 -> R2 | B5: =tam_responses.csv!B3 -> 4 | C5: =tam_responses.csv!C3 -> 4 | D5: =tam_responses.csv!D3 -> 4 | E5: =tam_responses.csv!E3 -> 4 | F5: =tam_responses.csv!F3 -> 4 | G5: =tam_responses.csv!G3 -> 3 | H5: =SUM(B5:G5) -> 23 | J5: =tam_responses.csv!A3 -> R2 | K5: =tam_responses.csv!I3 -> 4 | L5: =tam_responses.csv!J3 -> 4 | M5: =tam_responses.csv!K3 -> 4 | N5: =tam_responses.csv!L3 -> 3 | O5: =tam_responses.csv!M3 -> 4 | P5: =tam_responses.csv!N3 -> 3 | Q5: =SUM(K5:P5) -> 22
A6: =tam_responses.csv!A4 -> R3 | B6: =tam_responses.csv!B4 -> 4 | C6: =tam_responses.csv!C4 -> 4 | D6: =tam_responses.csv!D4 -> 3 | E6: =tam_responses.csv!E4 -> 4 | F6: =tam_responses.csv!F4 -> 4 | G6: =tam_responses.csv!G4 -> 3 | H6: =SUM(B6:G6) -> 22 | J6: =tam_responses.csv!A4 -> R3 | K6: =tam_responses.csv!I4 -> 4 | L6: =tam_responses.csv!J4 -> 4 | M6: =tam_responses.csv!K4 -> 4 | N6: =tam_responses.csv!L4 -> 3 | O6: =tam_responses.csv!M4 -> 3 | P6: =tam_responses.csv!N4 -> 5 | Q6: =SUM(K6:P6) -> 23
A7: =tam_responses.csv!A5 -> R4 | B7: =tam_responses.csv!B5 -> 4 | C7: =tam_responses.csv!C5 -> 4 | D7: =tam_responses.csv!D5 -> 4 | E7: =tam_responses.csv!E5 -> 5 | F7: =tam_responses.csv!F5 -> 5 | G7: =tam_responses.csv!G5 -> 5 | H7: =SUM(B7:G7) -> 27 | J7: =tam_responses.csv!A5 -> R4 | K7: =tam_responses.csv!I5 -> 4 | L7: =tam_responses.csv!J5 -> 4 | M7: =tam_responses.csv!K5 -> 5 | N7: =tam_responses.csv!L5 -> 5 | O7: =tam_responses.csv!M5 -> 5 | P7: =tam_responses.csv!N5 -> 3 | Q7: =SUM(K7:P7) -> 26
A8: =tam_responses.csv!A6 -> R5 | B8: =tam_responses.csv!B6 -> 4 | C8: =tam_responses.csv!C6 -> 4 | D8: =tam_responses.csv!D6 -> 4 | E8: =tam_responses.csv!E6 -> 4 | F8: =tam_responses.csv!F6 -> 3 | G8: =tam_responses.csv!G6 -> 3 | H8: =SUM(B8:G8) -> 22 | J8: =tam_responses.csv!A6 -> R5 | K8: =tam_responses.csv!I6 -> 4 | L8: =tam_responses.csv!J6 -> 5 | M8: =tam_responses.csv!K6 -> 5 | N8: =tam_responses.csv!L6 -> 4 | O8: =tam_responses.csv!M6 -> 3 | P8: =tam_responses.csv!N6 -> 5 | Q8: =SUM(K8:P8) -> 26
A9: =tam_responses.csv!A7 -> R6 | B9: =tam_responses.csv!B7 -> 4 | C9: =tam_responses.csv!C7 -> 4 | D9: =tam_responses.csv!D7 -> 4 | E9: =tam_responses.csv!E7 -> 4 | F9: =tam_responses.csv!F7 -> 4 | G9: =tam_responses.csv!G7 -> 4 | H9: =SUM(B9:G9) -> 24 | J9: =tam_responses.csv!A7 -> R6 | K9: =tam_responses.csv!I7 -> 3 | L9: =tam_responses.csv!J7 -> 3 | M9: =tam_responses.csv!K7 -> 3 | N9: =tam_responses.csv!L7 -> 4 | O9: =tam_responses.csv!M7 -> 4 | P9: =tam_responses.csv!N7 -> 4 | Q9: =SUM(K9:P9) -> 21
A10: =tam_responses.csv!A8 -> R7 | B10: =tam_responses.csv!B8 -> 4 | C10: =tam_responses.csv!C8 -> 4 | D10: =tam_responses.csv!D8 -> 4 | E10: =tam_responses.csv!E8 -> 4 | F10: =tam_responses.csv!F8 -> 4 | G10: =tam_responses.csv!G8 -> 4 | H10: =SUM(B10:G10) -> 24 | J10: =tam_responses.csv!A8 -> R7 | K10: =tam_responses.csv!I8 -> 4 | L10: =tam_responses.csv!J8 -> 4 | M10: =tam_responses.csv!K8 -> 4 | N10: =tam_responses.csv!L8 -> 4 | O10: =tam_responses.csv!M8 -> 4 | P10: =tam_responses.csv!N8 -> 4 | Q10: =SUM(K10:P10) -> 24
A11: =tam_responses.csv!A9 -> R8 | B11: =tam_responses.csv!B9 -> 4 | C11: =tam_responses.csv!C9 -> 4 | D11: =tam_responses.csv!D9 -> 4 | E11: =tam_responses.csv!E9 -> 4 | F11: =tam_responses.csv!F9 -> 4 | G11: =tam_responses.csv!G9 -> 4 | H11: =SUM(B11:G11) -> 24 | J11: =tam_responses.csv!A9 -> R8 | K11: =tam_responses.csv!I9 -> 4 | L11: =tam_responses.csv!J9 -> 4 | M11: =tam_responses.csv!K9 -> 4 | N11: =tam_responses.csv!L9 -> 4 | O11: =tam_responses.csv!M9 -> 4 | P11: =tam_responses.csv!N9 -> 4 | Q11: =SUM(K11:P11) -> 24
A12: =tam_responses.csv!A10 -> R9 | B12: =tam_responses.csv!B10 -> 4 | C12: =tam_responses.csv!C10 -> 4 | D12: =tam_responses.csv!D10 -> 5 | E12: =tam_responses.csv!E10 -> 5 | F12: =tam_responses.csv!F10 -> 5 | G12: =tam_responses.csv!G10 -> 5 | H12: =SUM(B12:G12) -> 28 | J12: =tam_responses.csv!A10 -> R9 | K12: =tam_responses.csv!I10 -> 5 | L12: =tam_responses.csv!J10 -> 5 | M12: =tam_responses.csv!K10 -> 5 | N12: =tam_responses.csv!L10 -> 5 | O12: =tam_responses.csv!M10 -> 5 | P12: =tam_responses.csv!N10 -> 5 | Q12: =SUM(K12:P12) -> 30
A13: =tam_responses.csv!A11 -> R10 | B13: =tam_responses.csv!B11 -> 5 | C13: =tam_responses.csv!C11 -> 5 | D13: =tam_responses.csv!D11 -> 5 | E13: =tam_responses.csv!E11 -> 5 | F13: =tam_responses.csv!F11 -> 4 | G13: =tam_responses.csv!G11 -> 3 | H13: =SUM(B13:G13) -> 27 | J13: =tam_responses.csv!A11 -> R10 | K13: =tam_responses.csv!I11 -> 3 | L13: =tam_responses.csv!J11 -> 3 | M13: =tam_responses.csv!K11 -> 3 | N13: =tam_responses.csv!L11 -> 3 | O13: =tam_responses.csv!M11 -> 3 | P13: =tam_responses.csv!N11 -> 3 | Q13: =SUM(K13:P13) -> 18
A14: =tam_responses.csv!A12 -> R11 | B14: =tam_responses.csv!B12 -> 5 | C14: =tam_responses.csv!C12 -> 5 | D14: =tam_responses.csv!D12 -> 5 | E14: =tam_responses.csv!E12 -> 5 | F14: =tam_responses.csv!F12 -> 5 | G14: =tam_responses.csv!G12 -> 5 | H14: =SUM(B14:G14) -> 30 | J14: =tam_responses.csv!A12 -> R11 | K14: =tam_responses.csv!I12 -> 5 | L14: =tam_responses.csv!J12 -> 5 | M14: =tam_responses.csv!K12 -> 5 | N14: =tam_responses.csv!L12 -> 4 | O14: =tam_responses.csv!M12 -> 5 | P14: =tam_responses.csv!N12 -> 5 | Q14: =SUM(K14:P14) -> 29
